sample-data/shareablee-responses/katy-perry-metrics.json
{
  "metrics": {
    "call_to_website_total_actions": 0,
    "offer_count": 0,
    "status_likes": 0,
    "status_percent_total_posts": 0,
    "photo_percent_total_actions": 80.99186732578536,
    "native_video_views": 1141686,
    "call_to_like_percent_total_actions": 0,
    "call_to_like_total_actions": 0,
    "link_count": 0,
    "includes_question_count": 0,
    "question_percent_total_actions": 0,
    "call_to_comment_total_actions": 0,
    "engagers_percent_male": 52.79968454258675,
    "video_shares": 991,
    "actions_per_male_engager": 1.1844660194174756,
    "link_shares": 0,
    "status_shares": 0,
    "photo_shares": 3230,
    "shares_percent_total_actions": 1.923138255461649,
    "frequency_day": 0.12903225806451613,
    "engagers_percent_new": 97.44342823861751,
    "link_comments": 0,
    "other_comments": 0,
    "latest_page_score": 55,
    "latest_fans": 70653185,
    "reactions_count": 210013,
    "comments_count": 5251,
    "includes_question_percent_total_actions": 0,
    "call_to_other_percent_total_posts": 0,
    "call_to_like_count": 0,
    "call_to_website_percent_total_actions": 0,
    "call_to_like_percent_total_posts": 0,
    "actions_per_female_engager": 1.1612364243943192,
    "shares_average": 1055.25,
    "question_percent_total_posts": 0,
    "offer_comments": 0,
    "other_count": 0,
    "call_to_website_percent_total_posts": 0,
    "call_to_other_percent_total_actions": 0,
    "status_percent_total_actions": 0,
    "call_to_other_count": 0,
    "likes_percent_total_actions": 81.55090325079163,
    "call_to_share_count": 1,
    "engagers_percent_female": 47.20031545741325,
    "link_likes": 0,
    "other_percent_total_actions": 0,
    "call_to_website_count": 0,
    "likes_count": 178992,
    "offer_percent_total_actions": 0,
    "question_comments": 0,
    "comments_percent_total_actions": 2.3924186163063537,
    "link_percent_total_posts": 0,
    "photo_percent_total_posts": 75,
    "video_percent_total_actions": 19.00813267421464,
    "includes_question_total_actions": 0,
    "status_comments": 0,
    "likes_average": 44748,
    "question_likes": 0,
    "call_to_comment_percent_total_actions": 0,
    "link_percent_total_actions": 0,
    "includes_question_percent_total_posts": 0,
    "actions_percent_female": 46.706989247311824,
    "post_count": 4,
    "total_actions": 219485,
    "offer_likes": 0,
    "other_shares": 0,
    "offer_percent_total_posts": 0,
    "question_count": 0,
    "offer_shares": 0,
    "photo_count": 3,
    "call_to_share_percent_total_posts": 25,
    "call_to_comment_percent_total_posts": 0,
    "status_count": 0,
    "question_shares": 0,
    "video_count": 1,
    "actions_per_engager": 1.1611755348097292,
    "comments_average": 1312.75,
    "call_to_other_total_actions": 0,
    "fan_average": 70733322.22580644,
    "call_to_comment_count": 0,
    "photo_comments": 3793,
    "call_to_share_percent_total_actions": 8.33952206301114,
    "total_modeled_impressions_count": 5915923,
    "other_likes": 0,
    "total_actions_percent_fans_per_post": 0.07757482368045862,
    "frequency_week": 0.9032258064516129,
    "engagers_percent_returning": 2.5565717613824828,
    "unique_engaged_audience": 189019,
    "shares_count": 4221,
    "video_comments": 1458,
    "photo_likes": 145994,
    "other_percent_total_posts": 0,
    "call_to_share_total_actions": 18304,
    "total_actions_average": 54871.25,
    "actions_percent_male": 53.293010752688176,
    "video_percent_total_posts": 25,
    "video_likes": 32998,
    "fans_by_country":
    [ { "code": "US",
      "percent": 22.906893330884635,
      "value": 340874,
      "full_name": "United States" },
      { "code": "MX",
        "percent": 13.087436335122863,
        "value": 194752,
        "full_name": "Mexico" },
      { "code": "BR",
        "percent": 7.758632574947624,
        "value": 115455,
        "full_name": "Brazil" },
      { "code": "ID",
        "percent": 5.107271925438846,
        "value": 76001,
        "full_name": "Indonesia" },
      { "code": "CO",
        "percent": 4.458494549476643,
        value: 66346,
        full_name: 'Colombia' },
      { code: 'CL',
        percent: 3.4873499196282145,
        value: 51895,
        full_name: 'Chile' },
      { code: 'AR',
        percent: 3.2055002257069365,
        value: 47701,
        full_name: 'Argentina' },
      { code: 'CA',
        percent: 2.8894216370316848,
        value: 42997,
        full_name: 'Canada' },
      { code: 'GB',
        percent: 2.721511457813614,
        value: 40498,
        full_name: 'United Kingdom' },
      { code: 'DE',
        percent: 2.4978638915205473,
        value: 37170,
        full_name: 'Germany' },
      { code: 'PH',
        percent: 2.418068729019357,
        value: 35983,
        full_name: 'Philippines' },
      { code: 'IT',
        percent: 2.404572269314592,
        value: 35782,
        full_name: 'Italy' },
      { code: 'IN',
        percent: 2.1005507492030895,
        value: 31258,
        full_name: 'India' },
      { code: 'PL',
        percent: 1.8316902596748335,
        value: 27257,
        full_name: 'Poland' },
      { code: 'FR',
        percent: 1.6277692888384587,
        value: 24223,
        full_name: 'France' },
      { code: 'ES',
        percent: 1.5779954033130625,
        value: 23482,
        full_name: 'Spain' },
      { code: 'EC',
        percent: 1.3952946130179578,
        value: 20763,
        full_name: 'Ecuador' },
      { code: 'TR',
        percent: 1.3777336075460171,
        value: 20502,
        full_name: 'Turkey' },
      { code: 'PE',
        percent: 1.3463358044037395,
        value: 20035,
        full_name: 'Peru' },
      { code: 'VE',
        percent: 1.3181050953232452,
        value: 19615,
        full_name: 'Venezuela' },
      { code: 'AU',
        percent: 1.2176100141389834,
        value: 18119,
        full_name: 'Australia' },
      { code: 'CR',
        percent: 0.955027351032989,
        value: 14212,
        full_name: 'Costa Rica' },
      { code: 'PT',
        percent: 0.8848418586042729,
        value: 13167,
        full_name: 'Portugal' },
      { code: 'GR',
        percent: 0.7965209049018553,
        value: 11853,
        full_name: 'Greece' },
      { code: 'FI',
        percent: 0.6889415914151247,
        value: 10252,
        full_name: 'Finland' },
      { code: 'RO',
        percent: 0.6778274974693598,
        value: 10087,
        full_name: 'Romania' },
      { code: 'BD',
        percent: 0.6646540336682261,
        value: 9891,
        full_name: 'Bangladesh' },
      { code: 'SE',
        percent: 0.6186693886767088,
        value: 9206,
        full_name: 'Sweden' },
      { code: 'MY',
        percent: 0.6178868281316687,
        value: 9195,
        full_name: 'Malaysia' },
      { code: 'NL',
        percent: 0.571061093136064,
        value: 8498,
        full_name: 'Netherlands' },
      { code: 'TH',
        percent: 0.5552494681623156,
        value: 8263,
        full_name: 'Thailand' },
      { code: 'BO',
        percent: 0.5536561662215828,
        value: 8239,
        full_name: 'Bolivia' },
      { code: 'BE',
        percent: 0.5402572556152296,
        value: 8039,
        full_name: 'Belgium' },
      { code: 'CZ',
        percent: 0.5318376845433845,
        value: 7914,
        full_name: 'Czechia' },
      { code: 'IR',
        percent: 0.5071924467689745,
        value: 7547,
        full_name: 'Iran' },
      { code: 'GT',
        percent: 0.47659021071819213,
        value: 7092,
        full_name: 'Guatemala' },
      { code: 'RS',
        percent: 0.44532680855594914,
        value: 6627,
        full_name: 'Serbia' },
      { code: 'BG',
        percent: 0.4432761097315501,
        value: 6596,
        full_name: 'Bulgaria' },
      { code: 'HU',
        percent: 0.4329359052998556,
        value: 6442,
        full_name: 'Hungary' },
      { code: 'NO',
        percent: 0.4246767483009549,
        value: 6320,
        full_name: 'Norway' },
