sample-data/shareablee-responses/metrics.json
{ metrics:
  { call_to_website_total_actions: 5184,
    offer_count: 0,
    status_likes: 0,
    status_percent_total_posts: 0,
    photo_percent_total_actions: 6.845038792098769,
    native_video_views: 34145916,
    call_to_like_percent_total_actions: 0.1080333127379415,
    call_to_like_total_actions: 1168,
    link_count: 480,
    includes_question_count: 117,
    question_percent_total_actions: 0,
    call_to_comment_total_actions: 589,
    engagers_percent_male: 26.693125252253463,
    video_shares: 218354,
    actions_per_male_engager: 1.6461871881457588,
    link_shares: 48781,
    status_shares: 0,
    photo_shares: 3018,
    shares_percent_total_actions: 24.98760576720301,
    frequency_day: 18.096774193548388,
    engagers_percent_new: 68.6643451622867,
    link_comments: 58696,
    other_comments: 0,
    latest_page_score: 85,
    latest_fans: 998674,
    reactions_count: 562197,
    comments_count: 248798,
    includes_question_percent_total_actions: 13.910306452030618,
    call_to_other_percent_total_posts: 0.17825311942959002,
    call_to_like_count: 2,
    call_to_website_percent_total_actions: 0.47949031954921995,
    call_to_like_percent_total_posts: 0.35650623885918004,
    actions_per_female_engager: 1.7751289251041495,
    shares_average: 481.5561497326203,
    question_percent_total_posts: 0,
    offer_comments: 0,
    other_count: 0,
    call_to_website_percent_total_posts: 2.13903743315508,
    call_to_other_percent_total_actions: 0.007862013341374168,
    status_percent_total_actions: 0,
    call_to_other_count: 1,
    likes_percent_total_actions: 44.682504152992934,
    call_to_share_count: 1,
    engagers_percent_female: 73.30687474774653,
    link_likes: 212669,
    other_percent_total_actions: 0,
    call_to_website_count: 12,
    likes_count: 483084,
    offer_percent_total_actions: 0,
    question_comments: 0,
    comments_percent_total_actions: 23.012390533026007,
    link_percent_total_posts: 85.56149732620321,
    photo_percent_total_posts: 4.81283422459893,
    video_percent_total_actions: 59.90946660401721,
    includes_question_total_actions: 150391,
    status_comments: 0,
    likes_average: 861.1122994652407,
    question_likes: 0,
    call_to_comment_percent_total_actions: 0.054479127741992775,
    link_percent_total_actions: 33.24549460388402,
    includes_question_percent_total_posts: 20.855614973262032,
    actions_percent_female: 74.75635110173356,
    post_count: 561,
    total_actions: 1081148,
    offer_likes: 0,
    other_shares: 0,
    offer_percent_total_posts: 0,
    question_count: 0,
    offer_shares: 0,
    photo_count: 27,
    call_to_share_percent_total_posts: 0.17825311942959002,
    call_to_comment_percent_total_posts: 0.35650623885918004,
    status_count: 0,
    question_shares: 0,
    video_count: 54,
    actions_per_engager: 1.8025106243870546,
    comments_average: 443.4901960784314,
    call_to_other_total_actions: 85,
    fan_average: 977710.4193548387,
    call_to_comment_count: 2,
    photo_comments: 1619,
    call_to_share_percent_total_actions: 0.020533728962177242,
    total_modeled_impressions_count: 261046813,
    other_likes: 0,
    total_actions_percent_fans_per_post: 0.1971115370666001,
    frequency_week: 126.67741935483872,
    engagers_percent_returning: 31.335654837713307,
    unique_engaged_audience: 599801,
    shares_count: 270153,
    video_comments: 188483,
    photo_likes: 61499,
    other_percent_total_posts: 0,
    call_to_share_total_actions: 222,
    total_actions_average: 1927.180035650624,
    actions_percent_male: 25.24364889826644,
    video_percent_total_posts: 9.62566844919786,
    video_likes: 208916
  },
  entity_id: '3750856',
  name: 'Time Out London',
  object_id: '297605497404'
}
